Workbook

Sheet Key Licensing Rules
A1: ORGANIZATION PRICING CONFIGURATION
A2: Enter your contracted rates and discounts below. All scenario sheets will automatically use these rates.
A4: BILLING OPTION | B4: STANDARD RATE | C4: YOUR DISCOUNT % | D4: YOUR RATE (After Discount) | E4: NOTES
A5: Pay-As-You-Go (PAYG) | B5: 0.01 | C5: 0 | D5: =B5*(1-C5/100) -> 0.01 | E5: Per credit rate
A6: Capacity Pack (Monthly) | B6: 200 | C6: 20 | D6: =B6*(1-C6/100) -> 160 | E6: $200/mo = 25,000 credits
A7: P3 Plan (Your Contracted Rate) | B7: 0.0095 | C7: 0 | D7: =B7*(1-C7/100) -> 0.0095 | E7: Enter your contracted P3 rate
A8: Hybrid (CP + P3) | B8: Calculated | C8: - | D8: Auto-calculated | E8: First 25K @ CP rate, overage @ P3 rate
A10: EFFECTIVE RATES SUMMARY (Referenced by all scenario sheets)
A11: PAYG Rate (per credit): | B11: =D5 -> 0.01
A12: Capacity Pack Cost (monthly): | B12: =D6 -> 160
A13: Capacity Pack Rate (per credit): | B13: =D6/25000 -> 0.0064
A14: P3 Rate (per credit): | B14: =D7 -> 0.0095
A15: Capacity Pack Credits: | B15: 25000
A17: INPUT CELL LEGEND
A18: Green cells: | B18: Editable - Enter your discount percentages
A19: White cells: | B19: Calculated or reference values (protected)
A21: BILLING OPTIONS COMPARISON CALCULATOR
A22: Enter your estimated monthly credits to compare all billing options
A24: Estimated Monthly Credits: | B24: 100000
A26: Billing Option | B26: Rate Applied | C26: Monthly Cost | D26: Annual Cost | E26: vs PAYG Savings | G26: Chart Data | H26: Monthly Cost
A27: Pay-As-You-Go (PAYG) | B27: =TEXT(D5,"$0.0000")&"/credit" -> $0.0100/credit | C27: =B24*D5 -> 1000 | D27: =C27*12 -> 12000 | E27: -- | G27: PAYG | H27: =C27 -> 1000
A28: Capacity Packs | B28: =TEXT(B13,"$0.0000")&"/credit" -> $0.0064/credit | C28: =IF(B24<25000, B24*(D6/25000), CEILING(B24/25000,1)*D6) -> 640 | D28: =C28*12 -> 7680 | E28: =C27-C28 -> 360 | G28: Capacity Packs | H28: =C28 -> 640
A29: P3 Plan | B29: $0.0095/credit | C29: =B24*D7 -> 950 | D29: =C29*12 -> 11400 | E29: =C27-C29 -> 50 | G29: P3 Plan | H29: =C29 -> 950
A30: Hybrid (CP + PAYG) | B30: Quotient×CP + Remainder×PAYG | C30: =IF(B24<B15, MIN(B24*D5, B24*(D6/B15)), QUOTIENT(B24,B15)*D6 + MOD(B24,B15)*D5) -> 640 | D30: =C30*12 -> 7680 | E30: =C27-C30 -> 360 | G30: CP + PAYG | H30: =C30 -> 640
A31: Hybrid (CP + P3) | B31: Quotient×CP + Remainder×P3 | C31: =IF(B24<B15, MIN(B24*D7, B24*(D6/B15)), QUOTIENT(B24,B15)*D6 + MOD(B24,B15)*D7) -> 640 | D31: =C31*12 -> 7680 | E31: =C27-C31 -> 360 | G31: CP + P3 | H31: =C31 -> 640
A33: BEST OPTION FOR YOUR USAGE: | B33: =INDEX(A27:A31,MATCH(MIN(C27:C31),C27:C31,0)) -> Capacity Packs | C33: ="Monthly: "&TEXT(MIN(C27:C31),"[$$-en-US]#,##0.00")&" | Annual: "&TEXT(MIN(C27:C31)*12,"[$$-en-US]#,##0.00") -> Monthly: $640.00 | Annual: $7,680.00

Sheet 1-Classic Answer
A1: Scenario 1: Classic Answer Calculator
A3: Classic answers are predefined, static responses. Best for FAQ bots, scripted menus, welcome messages.
A5: Credit Rate: 1 Copilot Credit per classic answer
A7: INPUT PARAMETERS | D7: ← Green cells are editable inputs
A8: Number of users per day: | B8: 1000
A9: Classic answers per user: | B9: 4
A10: Days per month: | B10: 30
A11: User Type (Licensed/Unlicensed): | B11: Unlicensed
A12: PAYG rate per credit: | B12: ='Key Licensing Rules'!$D$5 -> 0.01 | C12: ← From Key Licensing Rules (with discount)
A13: Capacity Pack cost: | B13: ='Key Licensing Rules'!$D$6 -> 160 | C13: ← From Key Licensing Rules (with discount)
A14: Capacity Pack credits: | B14: 25000
A16: CALCULATIONS
A17: Credits per day: | B17: =B8*B9*1 -> 4000
A18: Credits per month: | B18: =B17*B10 -> 120000
A19: Is User Licensed: | B19: =IF(UPPER(B11)="LICENSED","Yes","No") -> No
A20: Billable Credits: | B20: =IF(B19="Yes",0,B18) -> 120000
A22: COST COMPARISON
A23: Billing Model | B23: Calculation | C23: Monthly Cost | D23: Annual Cost | F23: Billing Option | G23: Monthly Cost
A24: Pay-As-You-Go (PAYG) | B24: =B20 & " × " & TEXT('Key Licensing Rules'!$B$11,"$0.0000") -> 120000 × $0.0100 | C24: =B20*'Key Licensing Rules'!$D$5 -> 1200 | D24: =C24*12 -> 14400 | F24: PAYG | G24: =C24 -> 1200
A25: Capacity Packs | B25: =CEILING(B20/25000,1) & " packs × " & TEXT('Key Licensing Rules'!$B$12,"$0.00") -> 5 packs × $160.00 | C25: =IF(B20<25000, B20*('Key Licensing Rules'!$D$6/25000), CEILING(B20/25000,1)*'Key Licensing Rules'!$D$6) -> 800 | D25: =C25*12 -> 9600 | F25: Capacity Packs | G25: =C25 -> 800
A26: P3 Plan | B26: =B20&" × "&TEXT('Key Licensing Rules'!$D$7,"[$$-en-US]#,##0.0000") -> 120000 × $0.0095 | C26: =B20*'Key Licensing Rules'!$D$7 -> 1140 | D26: =C26*12 -> 13680 | F26: P3 Plan | G26: =C26 -> 1140
A27: Hybrid (CP + PAYG) | B27: =IF(B20<25000, MIN(B20*'Key Licensing Rules'!$D$5, B20*('Key Licensing Rules'!$D$6/25000)), QUOTIENT(B20,25000)*'Key Licensing Rules'!$D$6 + MOD(B20,25000)*'Key Licensing Rules'!$D$5) -> 840 | C27: =B27*12 -> 10080 | D27: =C27*12 -> 120960 | F27: CP + PAYG | G27: =C27 -> 10080
A28: Hybrid (CP + P3) | B28: =IF(B20<25000, MIN(B20*'Key Licensing Rules'!$D$7, B20*('Key Licensing Rules'!$D$6/25000)), QUOTIENT(B20,25000)*'Key Licensing Rules'!$D$6 + MOD(B20,25000)*'Key Licensing Rules'!$D$7) -> 830 | C28: =B28*12 -> 9960 | D28: =C28*12 -> 119520 | F28: CP + P3 | G28: =C28 -> 9960
A30: RECOMMENDATION
A31: =INDEX(A24:A28,MATCH(MIN(C24:C28),C24:C28,0))&" is cheapest" -> Capacity Packs is cheapest | B31: ="Monthly: "&TEXT(MIN(C24:C28),"[$$-en-US]#,##0.00")&" | Annual: "&TEXT(MIN(C24:C28)*12,"[$$-en-US]#,##0.00") -> Monthly: $800.00 | Annual: $9,600.00
A33: 💡 NOTE: M365 Copilot licensed users (B2E) pay $0 for classic answers on internal channels

Sheet 2-Generative Answer
A1: Scenario 2: Generative Answer Calculator
A3: Generative answers are dynamically generated by AI using RAG. Best for knowledge bases, troubleshooting, product support.
A5: Credit Rate: 2 Copilot Credits per generative answer
A7: INPUT PARAMETERS | C7: ← Green cells are editable inputs
A8: Number of users per day: | B8: 900
A9: Classic answers per user: | B9: 4
A10: Generative answers per user: | B10: 2
A11: Days per month: | B11: 30
A12: User Type (Licensed/Unlicensed): | B12: Unlicensed
A13: PAYG rate per credit: | B13: ='Key Licensing Rules'!$D$5 -> 0.01 | C13: ← From Key Licensing Rules
A14: Capacity Pack cost: | B14: ='Key Licensing Rules'!$D$6 -> 160 | C14: ← From Key Licensing Rules
A15: Capacity Pack credits: | B15: 25000
A17: CALCULATIONS
A18: Credits per session: | B18: =(B9*1)+(B10*2) -> 8 | C18: (classic×1 + generative×2)
A19: Credits per day: | B19: =B18*B8 -> 7200
A20: Credits per month: | B20: =B19*B11 -> 216000
A21: Is User Licensed: | B21: =IF(UPPER(B12)="LICENSED","Yes","No") -> No
A22: Billable Credits: | B22: =IF(B21="Yes",0,B20) -> 216000
A24: COST COMPARISON
A25: Billing Model | B25: Monthly Cost | C25: Annual Cost | E25: Billing Option | F25: Monthly Cost
A26: Pay-As-You-Go (PAYG) | B26: =B22*'Key Licensing Rules'!$D$5 -> 2160 | C26: =B26*12 -> 25920 | E26: PAYG | F26: =B26 -> 2160
A27: Capacity Packs | B27: =IF(B22<25000, B22*('Key Licensing Rules'!$D$6/25000), CEILING(B22/25000,1)*'Key Licensing Rules'!$D$6) -> 1440 | C27: =B27*12 -> 17280 | E27: Capacity Packs | F27: =B27 -> 1440
A28: P3 Plan | B28: =B22*'Key Licensing Rules'!$D$7 -> 2052 | C28: =B28*12 -> 24624 | E28: P3 Plan | F28: =B28 -> 2052
A29: Hybrid (CP + PAYG) | B29: =IF(B22<25000, MIN(B22*'Key Licensing Rules'!$D$5, B22*('Key Licensing Rules'!$D$6/25000)), QUOTIENT(B22,25000)*'Key Licensing Rules'!$D$6 + MOD(B22,25000)*'Key Licensing Rules'!$D$5) -> 1440 | C29: =B29*12 -> 17280 | E29: CP + PAYG | F29: =B29 -> 1440
A30: Hybrid (CP + P3) | B30: =IF(B22<25000, MIN(B22*'Key Licensing Rules'!$D$7, B22*('Key Licensing Rules'!$D$6/25000)), QUOTIENT(B22,25000)*'Key Licensing Rules'!$D$6 + MOD(B22,25000)*'Key Licensing Rules'!$D$7) -> 1432 | C30: =B30*12 -> 17184 | E30: CP + P3 | F30: =B30 -> 1432
A32: RECOMMENDATION
A33: RECOMMENDATION | B33: ="Monthly: "&TEXT(MIN(B26:B30),"[$$-en-US]#,##0.00")&" | Annual: "&TEXT(MIN(B26:B30)*12,"[$$-en-US]#,##0.00") -> Monthly: $1,432.00 | Annual: $17,184.00
A34: =INDEX(A26:A30,MATCH(MIN(B26:B30),B26:B30,0))&" is cheapest" -> Hybrid (CP + P3) is cheapest | B34: ="Monthly: "&TEXT(MIN(B26:B30),"[$$-en-US]#,##0.00")&" | Annual: "&TEXT(MIN(B26:B30)*12,"[$$-en-US]#,##0.00") -> Monthly: $1,432.00 | Annual: $17,184.00

Sheet 3-Agent Action
A1: Scenario 3: Agent with Action
A3: Agent actions include API calls, connector invocations, topic transitions. Best for CRM updates, ticket creation, system lookups.
A5: Credit Rate: 5 Copilot Credits per agent action
A7: INPUT PARAMETERS | D7: ← Green cells are editable inputs
A8: Number of interactions per month: | B8: 1500
A9: % that are FAQ (generative only): | B9: 60
A10: % that include action (gen+action): | B10: 40
A11: User Type (Licensed/Unlicensed): | B11: Unlicensed
A12: PAYG rate per credit: | B12: ='Key Licensing Rules'!$D$5 -> 0.01 | C12: ← From Key Licensing Rules
A13: Capacity Pack cost: | B13: ='Key Licensing Rules'!$D$6 -> 160 | C13: ← From Key Licensing Rules
A14: Capacity Pack credits: | B14: 25000
A16: CALCULATIONS
A17: FAQ interactions: | B17: =B8*(B9/100) -> 900
A18: Action interactions: | B18: =B8*(B10/100) -> 600
A19: FAQ credits (2 each): | B19: =B17*2 -> 1800
A20: Action credits (7 each = 2+5): | B20: =B18*7 -> 4200
A21: Total credits per month: | B21: =B19+B20 -> 6000
A22: Is User Licensed: | B22: =IF(UPPER(B11)="LICENSED","Yes","No") -> No
A23: Billable Credits: | B23: =IF(B22="Yes",0,B21) -> 6000
A25: COST COMPARISON
A26: Billing Model | B26: Monthly Cost | C26: Annual Cost | E26: Billing Option | F26: Monthly Cost
A27: Pay-As-You-Go (PAYG) | B27: =B23*'Key Licensing Rules'!$D$5 -> 60 | C27: =B27*12 -> 720 | E27: PAYG | F27: =B27 -> 60
A28: Capacity Packs | B28: =IF(B23<25000, B23*('Key Licensing Rules'!$D$6/25000), CEILING(B23/25000,1)*'Key Licensing Rules'!$D$6) -> 38.4 | C28: =B28*12 -> 460.8 | E28: Capacity Packs | F28: =B28 -> 38.4
A29: P3 Plan | B29: =B23*'Key Licensing Rules'!$D$7 -> 57 | C29: =B29*12 -> 684 | E29: P3 Plan | F29: =B29 -> 57
A30: Hybrid (CP + PAYG) | B30: =IF(B23<25000, MIN(B23*'Key Licensing Rules'!$D$5, B23*('Key Licensing Rules'!$D$6/25000)), QUOTIENT(B23,25000)*'Key Licensing Rules'!$D$6 + MOD(B23,25000)*'Key Licensing Rules'!$D$5) -> 38.4 | C30: =B30*12 -> 460.8 | E30: CP + PAYG | F30: =B30 -> 38.4
A31: Hybrid (CP + P3) | B31: =IF(B23<25000, MIN(B23*'Key Licensing Rules'!$D$7, B23*('Key Licensing Rules'!$D$6/25000)), QUOTIENT(B23,25000)*'Key Licensing Rules'!$D$6 + MOD(B23,25000)*'Key Licensing Rules'!$D$7) -> 38.4 | C31: =B31*12 -> 460.8 | E31: CP + P3 | F31: =B31 -> 38.4
A33: RECOMMENDATION
A34: RECOMMENDATION | B34: ="Monthly: "&TEXT(MIN(B27:B31),"[$$-en-US]#,##0.00")&" | Annual: "&TEXT(MIN(B27:B31)*12,"[$$-en-US]#,##0.00") -> Monthly: $38.40 | Annual: $460.80
A35: =INDEX(A27:A31,MATCH(MIN(B27:B31),B27:B31,0))&" is cheapest" -> Capacity Packs is cheapest | B35: ="Monthly: "&TEXT(MIN(B27:B31),"[$$-en-US]#,##0.00")&" | Annual: "&TEXT(MIN(B27:B31)*12,"[$$-en-US]#,##0.00") -> Monthly: $38.40 | Annual: $460.80

Sheet 4-Graph Grounding
A1: Scenario 4: Agent with Tenant Graph Grounding
A3: Tenant Graph grounding queries Microsoft Graph (emails, files, meetings). Adds 10 credits on top of base response cost.
A5: Credit Rate: 10 credits per Graph grounding + 2 for generative = 12 credits total per grounded response
A7: INPUT PARAMETERS | C7: ← Green cells are editable inputs
A8: Licensed users per day: | B8: 50
A9: Unlicensed users per day: | B9: 100
A10: Generative answers per user: | B10: 4
A11: Graph grounding per user: | B11: 4
A12: Days per month: | B12: 30
A13: PAYG rate per credit: | B13: ='Key Licensing Rules'!$D$5 -> 0.01 | C13: ← From Key Licensing Rules
A14: Capacity Pack cost: | B14: ='Key Licensing Rules'!$D$6 -> 160 | C14: ← From Key Licensing Rules
A15: Capacity Pack credits: | B15: 25000
A17: CALCULATIONS
A18: Credits per unlicensed user: | B18: =(B10*2)+(B11*10) -> 48 | C18: (gen×2 + graph×10)
A19: Daily unlicensed credits: | B19: =B18*B9 -> 4800
A20: Monthly credits (unlicensed): | B20: =B19*B12 -> 144000
A21: Licensed user cost: | B21: $0 (included) | C21: $0 (included)
A23: COST COMPARISON (Unlicensed Users Only)
A24: Billing Model | B24: Monthly Cost | C24: Annual Cost | E24: Billing Option | F24: Monthly Cost
A25: Pay-As-You-Go (PAYG) | B25: =B20*'Key Licensing Rules'!$D$5 -> 1440 | C25: =B25*12 -> 17280 | E25: PAYG | F25: =B25 -> 1440
A26: Capacity Packs | B26: =IF(B20<25000, B20*('Key Licensing Rules'!$D$6/25000), CEILING(B20/25000,1)*'Key Licensing Rules'!$D$6) -> 960 | C26: =B26*12 -> 11520 | E26: Capacity Packs | F26: =B26 -> 960
A27: P3 Plan | B27: =B20*'Key Licensing Rules'!$D$7 -> 1368 | C27: =B27*12 -> 16416 | E27: P3 Plan | F27: =B27 -> 1368
A28: Hybrid (CP + PAYG) | B28: =IF(B20<25000, MIN(B20*'Key Licensing Rules'!$D$5, B20*('Key Licensing Rules'!$D$6/25000)), QUOTIENT(B20,25000)*'Key Licensing Rules'!$D$6 + MOD(B20,25000)*'Key Licensing Rules'!$D$5) -> 990 | C28: =B28*12 -> 11880 | E28: CP + PAYG | F28: =B28 -> 990
A29: Hybrid (CP + P3) | B29: =IF(B20<25000, MIN(B20*'Key Licensing Rules'!$D$7, B20*('Key Licensing Rules'!$D$6/25000)), QUOTIENT(B20,25000)*'Key Licensing Rules'!$D$6 + MOD(B20,25000)*'Key Licensing Rules'!$D$7) -> 980.5 | C29: =B29*12 -> 11766 | E29: CP + P3 | F29: =B29 -> 980.5
A31: RECOMMENDATION
A32: RECOMMENDATION | B32: ="Monthly: "&TEXT(MIN(B25:B29),"[$$-en-US]#,##0.00")&" | Annual: "&TEXT(MIN(B25:B29)*12,"[$$-en-US]#,##0.00") -> Monthly: $960.00 | Annual: $11,520.00
A33: =INDEX(A25:A29,MATCH(MIN(B25:B29),B25:B29,0))&" is cheapest" -> Capacity Packs is cheapest | B33: ="Monthly: "&TEXT(MIN(B25:B29),"[$$-en-US]#,##0.00")&" | Annual: "&TEXT(MIN(B25:B29)*12,"[$$-en-US]#,##0.00") -> Monthly: $960.00 | Annual: $11,520.00

Sheet 5-Agent Flow Actions
A1: Scenario 5: Agent Flow Actions Calculator
A3: Agent flows are Power Automate flows embedded in agents. Billed per 100 flow actions (13 credits per 100).
A5: Credit Rate: 13 Copilot Credits per 100 flow actions (~0.13 credits per action)
A7: INPUT PARAMETERS | D7: ← Green cells are editable inputs
A8: Number of triggers per month: | B8: 5000
A9: Flow actions per trigger: | B9: 20
A10: Agent actions per trigger: | B10: 2
A11: User Type (Licensed/Unlicensed): | B11: Unlicensed
A12: PAYG rate per credit: | B12: ='Key Licensing Rules'!$D$5 -> 0.01 | C12: ← From Key Licensing Rules
A13: Capacity Pack cost: | B13: ='Key Licensing Rules'!$D$6 -> 160 | C13: ← From Key Licensing Rules
A14: Capacity Pack credits: | B14: 25000
A16: CALCULATIONS
A17: Flow credits per trigger: | B17: =(B9/100)*13 -> 2.6 | C17: (actions/100 × 13)
A18: Agent action credits per trigger: | B18: =B10*5 -> 10
A19: Total credits per trigger: | B19: =B17+B18 -> 12.6
A20: Total monthly credits: | B20: =B19*B8 -> 63000
A21: Is User Licensed: | B21: =IF(UPPER(B11)="LICENSED","Yes","No") -> No
A22: Billable Credits: | B22: =IF(B21="Yes",0,B20) -> 63000
A24: COST COMPARISON
A25: Billing Model | B25: Monthly Cost | C25: Annual Cost | E25: Billing Option | F25: Monthly Cost
A26: Pay-As-You-Go (PAYG) | B26: =B22*'Key Licensing Rules'!$D$5 -> 630 | C26: =B26*12 -> 7560 | E26: PAYG | F26: =B26 -> 630
A27: Capacity Packs | B27: =IF(B22<25000, B22*('Key Licensing Rules'!$D$6/25000), CEILING(B22/25000,1)*'Key Licensing Rules'!$D$6) -> 480 | C27: =B27*12 -> 5760 | E27: Capacity Packs | F27: =B27 -> 480
A28: P3 Plan | B28: =B22*'Key Licensing Rules'!$D$7 -> 598.5 | C28: =B28*12 -> 7182 | E28: P3 Plan | F28: =B28 -> 598.5
A29: Hybrid (CP + PAYG) | B29: =IF(B22<25000, MIN(B22*'Key Licensing Rules'!$D$5, B22*('Key Licensing Rules'!$D$6/25000)), QUOTIENT(B22,25000)*'Key Licensing Rules'!$D$6 + MOD(B22,25000)*'Key Licensing Rules'!$D$5) -> 450 | C29: =B29*12 -> 5400 | E29: CP + PAYG | F29: =B29 -> 450
A30: Hybrid (CP + P3) | B30: =IF(B22<25000, MIN(B22*'Key Licensing Rules'!$D$7, B22*('Key Licensing Rules'!$D$6/25000)), QUOTIENT(B22,25000)*'Key Licensing Rules'!$D$6 + MOD(B22,25000)*'Key Licensing Rules'!$D$7) -> 443.5 | C30: =B30*12 -> 5322 | E30: CP + P3 | F30: =B30 -> 443.5
A32: RECOMMENDATION
A33: RECOMMENDATION | B33: ="Monthly: "&TEXT(MIN(B26:B30),"[$$-en-US]#,##0.00")&" | Annual: "&TEXT(MIN(B26:B30)*12,"[$$-en-US]#,##0.00") -> Monthly: $443.50 | Annual: $5,322.00
A34: =INDEX(A26:A30,MATCH(MIN(B26:B30),B26:B30,0))&" is cheapest" -> Hybrid (CP + P3) is cheapest | B34: ="Monthly: "&TEXT(MIN(B26:B30),"[$$-en-US]#,##0.00")&" | Annual: "&TEXT(MIN(B26:B30)*12,"[$$-en-US]#,##0.00") -> Monthly: $443.50 | Annual: $5,322.00

Sheet 6-Autonomous Trigger
A1: Scenario 6: Autonomous Triggers Calculator
A3: Autonomous triggers fire when agent activates itself based on event/schedule. ALWAYS BILLED - even for licensed users!
A5: ⚠️ CRITICAL: 25 Copilot Credits per autonomous trigger - ALWAYS BILLED regardless of user license!
A7: INPUT PARAMETERS | D7: ← Green cells are editable inputs
A8: Autonomous triggers per month: | B8: 800
A9: Pages processed per trigger: | B9: 0
A10: Generative answers per trigger: | B10: 1
A11: Agent actions per trigger: | B11: 3
A12: PAYG rate per credit: | B12: ='Key Licensing Rules'!$D$5 -> 0.01 | C12: ← From Key Licensing Rules
A13: Capacity Pack cost: | B13: ='Key Licensing Rules'!$D$6 -> 160 | C13: ← From Key Licensing Rules
A14: Capacity Pack credits: | B14: 25000
A16: CALCULATIONS (Per Trigger Breakdown)
A17: Autonomous trigger credits: | B17: 25 | C17: (always 25)
A18: Content processing credits: | B18: =B9*8 -> 0 | C18: (pages × 8)
A19: Generative answer credits: | B19: =B10*2 -> 2 | C19: (answers × 2)
A20: Agent action credits: | B20: =B11*5 -> 15 | C20: (actions × 5)
A21: Total credits per trigger: | B21: =B17+B18+B19+B20 -> 42
A22: Total monthly credits: | B22: =B21*B8 -> 33600
A24: COST COMPARISON
A25: Billing Model | B25: Monthly Cost | C25: Annual Cost | E25: Billing Option | F25: Monthly Cost
A26: Pay-As-You-Go (PAYG) | B26: =B22*'Key Licensing Rules'!$D$5 -> 336 | C26: =B26*12 -> 4032 | E26: PAYG | F26: =B26 -> 336
A27: Capacity Packs | B27: =IF(B22<25000, B22*('Key Licensing Rules'!$D$6/25000), CEILING(B22/25000,1)*'Key Licensing Rules'!$D$6) -> 320 | C27: =B27*12 -> 3840 | E27: Capacity Packs | F27: =B27 -> 320
A28: P3 Plan | B28: =B22*'Key Licensing Rules'!$D$7 -> 319.2 | C28: =B28*12 -> 3830.4 | E28: P3 Plan | F28: =B28 -> 319.2
A29: Hybrid (CP + PAYG) | B29: =IF(B22<25000, MIN(B22*'Key Licensing Rules'!$D$5, B22*('Key Licensing Rules'!$D$6/25000)), QUOTIENT(B22,25000)*'Key Licensing Rules'!$D$6 + MOD(B22,25000)*'Key Licensing Rules'!$D$5) -> 246 | C29: =B29*12 -> 2952 | E29: CP + PAYG | F29: =B29 -> 246
A30: Hybrid (CP + P3) | B30: =IF(B22<25000, MIN(B22*'Key Licensing Rules'!$D$7, B22*('Key Licensing Rules'!$D$6/25000)), QUOTIENT(B22,25000)*'Key Licensing Rules'!$D$6 + MOD(B22,25000)*'Key Licensing Rules'!$D$7) -> 241.7 | C30: =B30*12 -> 2900.4 | E30: CP + P3 | F30: =B30 -> 241.7
A32: 💡 DESIGN TIP
A33: Consider batching - trigger on schedule to process accumulated events instead of per-event triggers.
A35: RECOMMENDATION
A36: RECOMMENDATION | B36: ="Monthly: "&TEXT(MIN(B26:B30),"[$$-en-US]#,##0.00")&" | Annual: "&TEXT(MIN(B26:B30)*12,"[$$-en-US]#,##0.00") -> Monthly: $241.70 | Annual: $2,900.40
A37: =INDEX(A26:A30,MATCH(MIN(B26:B30),B26:B30,0))&" is cheapest" -> Hybrid (CP + P3) is cheapest | B37: ="Monthly: "&TEXT(MIN(B26:B30),"[$$-en-US]#,##0.00")&" | Annual: "&TEXT(MIN(B26:B30)*12,"[$$-en-US]#,##0.00") -> Monthly: $241.70 | Annual: $2,900.40

Sheet 7-AI Tools
A1: Scenario 7: AI Tools Calculator (Basic, Standard, Premium)
A3: AI TOOLS CREDIT RATES
A4: Tool Tier | B4: Credits per 10 responses | C4: Use Cases
A5: Basic | B5: 1 | C5: Sentiment analysis, language detection, key phrase extraction
A6: Standard | B6: 15 | C6: Text translation, entity extraction, category classification
A7: Premium | B7: 100 | C7: Deep reasoning, advanced LLM prompts, Code Interpreter
A9: INPUT PARAMETERS | D9: ← Green cells are editable inputs
A10: Basic AI responses per month: | B10: 30000
A11: Standard AI responses per month: | B11: 45000
A12: Premium AI responses per month: | B12: 5000
A13: User Type (Licensed/Unlicensed): | B13: Unlicensed
A14: PAYG rate per credit: | B14: ='Key Licensing Rules'!$D$5 -> 0.01 | C14: ← From Key Licensing Rules
A15: Capacity Pack cost: | B15: ='Key Licensing Rules'!$D$6 -> 160 | C15: ← From Key Licensing Rules
A16: Capacity Pack credits: | B16: 25000
A18: CALCULATIONS
A19: Basic credits: | B19: =(B10/10)*1 -> 3000 | C19: (responses/10 × 1)
A20: Standard credits: | B20: =(B11/10)*15 -> 67500 | C20: (responses/10 × 15)
A21: Premium credits: | B21: =(B12/10)*100 -> 50000 | C21: (responses/10 × 100)
A22: Total monthly credits: | B22: =B19+B20+B21 -> 120500
A23: Is User Licensed: | B23: =IF(UPPER(B13)="LICENSED","Yes","No") -> No
A24: Billable Credits: | B24: =IF(B23="Yes",0,B22) -> 120500
A26: COST COMPARISON
A27: Billing Model | B27: Monthly Cost | C27: Annual Cost | E27: Billing Option | F27: Monthly Cost
A28: Pay-As-You-Go (PAYG) | B28: =B24*'Key Licensing Rules'!$D$5 -> 1205 | C28: =B28*12 -> 14460 | E28: PAYG | F28: =B28 -> 1205
A29: Capacity Packs | B29: =IF(B24<25000, B24*('Key Licensing Rules'!$D$6/25000), CEILING(B24/25000,1)*'Key Licensing Rules'!$D$6) -> 800 | C29: =B29*12 -> 9600 | E29: Capacity Packs | F29: =B29 -> 800
A30: P3 Plan | B30: =B24*'Key Licensing Rules'!$D$7 -> 1144.75 | C30: =B30*12 -> 13737 | E30: P3 Plan | F30: =B30 -> 1144.75
A31: Hybrid (CP + PAYG) | B31: =IF(B24<25000, MIN(B24*'Key Licensing Rules'!$D$5, B24*('Key Licensing Rules'!$D$6/25000)), QUOTIENT(B24,25000)*'Key Licensing Rules'!$D$6 + MOD(B24,25000)*'Key Licensing Rules'!$D$5) -> 845 | C31: =B31*12 -> 10140 | E31: CP + PAYG | F31: =B31 -> 845
A32: Hybrid (CP + P3) | B32: =IF(B24<25000, MIN(B24*'Key Licensing Rules'!$D$7, B24*('Key Licensing Rules'!$D$6/25000)), QUOTIENT(B24,25000)*'Key Licensing Rules'!$D$6 + MOD(B24,25000)*'Key Licensing Rules'!$D$7) -> 834.75 | C32: =B32*12 -> 10017 | E32: CP + P3 | F32: =B32 -> 834.75
A34: RECOMMENDATION
A35: RECOMMENDATION | B35: ="Monthly: "&TEXT(MIN(B28:B32),"[$$-en-US]#,##0.00")&" | Annual: "&TEXT(MIN(B28:B32)*12,"[$$-en-US]#,##0.00") -> Monthly: $800.00 | Annual: $9,600.00
A36: =INDEX(A28:A32,MATCH(MIN(B28:B32),B28:B32,0))&" is cheapest" -> Capacity Packs is cheapest | B36: ="Monthly: "&TEXT(MIN(B28:B32),"[$$-en-US]#,##0.00")&" | Annual: "&TEXT(MIN(B28:B32)*12,"[$$-en-US]#,##0.00") -> Monthly: $800.00 | Annual: $9,600.00

Sheet 8-Content Processing
A1: Scenario 8: Content Processing Tools Calculator
A3: Document processing: invoice/receipt processing, OCR, identity documents, business cards. Available in agent flows.
A5: Credit Rate: 8 Copilot Credits per page processed
A7: INPUT PARAMETERS | D7: ← Green cells are editable inputs
A8: Documents per month: | B8: 500
A9: Average pages per document: | B9: 5
A10: User Type (Licensed/Unlicensed): | B10: Unlicensed
A11: PAYG rate per credit: | B11: ='Key Licensing Rules'!$D$5 -> 0.01 | C11: ← From Key Licensing Rules
A12: Capacity Pack cost: | B12: ='Key Licensing Rules'!$D$6 -> 160 | C12: ← From Key Licensing Rules
A13: Capacity Pack credits: | B13: 25000
A15: CALCULATIONS
A16: Total pages per month: | B16: =B8*B9 -> 2500
A17: Credits per page: | B17: 8
A18: Total monthly credits: | B18: =B16*B17 -> 20000
A19: Cost per document: | B19: =B17*B11 -> 0.08
A20: Is User Licensed: | B20: =IF(UPPER(B10)="LICENSED","Yes","No") -> No
A21: Billable Credits: | B21: =IF(B20="Yes",0,B18) -> 20000
A23: COST COMPARISON
A24: Billing Model | B24: Monthly Cost | C24: Annual Cost | E24: Billing Option | F24: Monthly Cost
A25: Pay-As-You-Go (PAYG) | B25: =B21*'Key Licensing Rules'!$D$5 -> 200 | C25: =B25*12 -> 2400 | E25: PAYG | F25: =B25 -> 200
A26: Capacity Packs | B26: =IF(B21<25000, B21*('Key Licensing Rules'!$D$6/25000), CEILING(B21/25000,1)*'Key Licensing Rules'!$D$6) -> 128 | C26: =B26*12 -> 1536 | E26: Capacity Packs | F26: =B26 -> 128
A27: P3 Plan | B27: =B21*'Key Licensing Rules'!$D$7 -> 190 | C27: =B27*12 -> 2280 | E27: P3 Plan | F27: =B27 -> 190
A28: Hybrid (CP + PAYG) | B28: =IF(B21<25000, MIN(B21*'Key Licensing Rules'!$D$5, B21*('Key Licensing Rules'!$D$6/25000)), QUOTIENT(B21,25000)*'Key Licensing Rules'!$D$6 + MOD(B21,25000)*'Key Licensing Rules'!$D$5) -> 128 | C28: =B28*12 -> 1536 | E28: CP + PAYG | F28: =B28 -> 128
A29: Hybrid (CP + P3) | B29: =IF(B21<25000, MIN(B21*'Key Licensing Rules'!$D$7, B21*('Key Licensing Rules'!$D$6/25000)), QUOTIENT(B21,25000)*'Key Licensing Rules'!$D$6 + MOD(B21,25000)*'Key Licensing Rules'!$D$7) -> 128 | C29: =B29*12 -> 1536 | E29: CP + P3 | F29: =B29 -> 128
A31: RECOMMENDATION
A32: RECOMMENDATION | B32: ="Monthly: "&TEXT(MIN(B25:B29),"[$$-en-US]#,##0.00")&" | Annual: "&TEXT(MIN(B25:B29)*12,"[$$-en-US]#,##0.00") -> Monthly: $128.00 | Annual: $1,536.00
A33: =INDEX(A25:A29,MATCH(MIN(B25:B29),B25:B29,0))&" is cheapest" -> Capacity Packs is cheapest | B33: ="Monthly: "&TEXT(MIN(B25:B29),"[$$-en-US]#,##0.00")&" | Annual: "&TEXT(MIN(B25:B29)*12,"[$$-en-US]#,##0.00") -> Monthly: $128.00 | Annual: $1,536.00

Sheet 9-Combined Features
A1: Scenario 9: Combined Multi-Feature Interaction Calculator
A3: Real-world deployments trigger multiple billable features in a single interaction. Credits stack per feature used.
A5: CREDIT RATES REFERENCE
A6: Feature | B6: Credits
A7: Classic answer | B7: 1
A8: Generative answer | B8: 2
A9: Agent action | B9: 5
A10: Graph grounding | B10: 10
A11: Autonomous trigger | B11: 25
A12: Content processing (per page) | B12: 8
A13: AI Basic (per 10 responses) | B13: 1
A14: AI Standard (per 10 responses) | B14: 15
A15: AI Premium (per 10 responses) | B15: 100 | C15: (= 10 credits per individual response)
A17: INTERACTION SCENARIOS - CREDITS PER INTERACTION
A18: # | B18: Interaction Scenario | C18: Classic | D18: Generative | E18: Graph | F18: Actions | G18: Autonomous | H18: Pages | I18: AI Basic (responses) | J18: AI Standard (responses) | K18: AI Premium (responses) | L18: Credits/Interaction
A19: 1 | B19: Simple FAQ (classic) | C19: 1 | D19: 0 | E19: 0 | F19: 0 | G19: 0 | H19: 0 | I19: 0 | J19: 0 | K19: 0 | L19: =C19*$B$7 + D19*$B$8 + E19*$B$10 + F19*$B$9 + G19*$B$11 + H19*$B$12 + I19*($B$13/10) + J19*($B$14/10) + K19*($B$15/10) -> 1
A20: 2 | B20: AI-generated response | C20: 0 | D20: 1 | E20: 0 | F20: 0 | G20: 0 | H20: 0 | I20: 0 | J20: 0 | K20: 0 | L20: =C20*$B$7 + D20*$B$8 + E20*$B$10 + F20*$B$9 + G20*$B$11 + H20*$B$12 + I20*($B$13/10) + J20*($B$14/10) + K20*($B$15/10) -> 2
A21: 3 | B21: Generative + Graph grounding | C21: 0 | D21: 1 | E21: 1 | F21: 0 | G21: 0 | H21: 0 | I21: 0 | J21: 0 | K21: 0 | L21: =C21*$B$7 + D21*$B$8 + E21*$B$10 + F21*$B$9 + G21*$B$11 + H21*$B$12 + I21*($B$13/10) + J21*($B$14/10) + K21*($B$15/10) -> 12
A22: 4 | B22: Generative + 1 API action | C22: 0 | D22: 1 | E22: 0 | F22: 1 | G22: 0 | H22: 0 | I22: 0 | J22: 0 | K22: 0 | L22: =C22*$B$7 + D22*$B$8 + E22*$B$10 + F22*$B$9 + G22*$B$11 + H22*$B$12 + I22*($B$13/10) + J22*($B$14/10) + K22*($B$15/10) -> 7
A23: 5 | B23: Generative + Graph + 2 actions | C23: 0 | D23: 1 | E23: 1 | F23: 2 | G23: 0 | H23: 0 | I23: 0 | J23: 0 | K23: 0 | L23: =C23*$B$7 + D23*$B$8 + E23*$B$10 + F23*$B$9 + G23*$B$11 + H23*$B$12 + I23*($B$13/10) + J23*($B$14/10) + K23*($B$15/10) -> 22
A24: 6 | B24: Full autonomous invoice processing | C24: 0 | D24: 1 | E24: 0 | F24: 2 | G24: 1 | H24: 5 | I24: 0 | J24: 0 | K24: 0 | L24: =C24*$B$7 + D24*$B$8 + E24*$B$10 + F24*$B$9 + G24*$B$11 + H24*$B$12 + I24*($B$13/10) + J24*($B$14/10) + K24*($B$15/10) -> 77
A25: 7 | B25: Deep reasoning + action + Graph | C25: 0 | D25: 1 | E25: 1 | F25: 1 | G25: 0 | H25: 0 | I25: 0 | J25: 0 | K25: 1 | L25: =C25*$B$7 + D25*$B$8 + E25*$B$10 + F25*$B$9 + G25*$B$11 + H25*$B$12 + I25*($B$13/10) + J25*($B$14/10) + K25*($B$15/10) -> 27
A26: 8 | B26: Autonomous + translation + 3 actions | C26: 0 | D26: 1 | E26: 0 | F26: 3 | G26: 1 | H26: 0 | I26: 0 | J26: 0 | K26: 0 | L26: =C26*$B$7 + D26*$B$8 + E26*$B$10 + F26*$B$9 + G26*$B$11 + H26*$B$12 + I26*($B$13/10) + J26*($B$14/10) + K26*($B$15/10) -> 42
A28: INPUT: MONTHLY INTERACTION VOLUMES | D28: ← Green cells are editable inputs
A29: # | B29: Interaction Scenario | C29: Monthly Volume
A30: 1 | B30: Simple FAQ (classic) | C30: 2000
A31: 2 | B31: AI-generated response | C31: 3000
A32: 3 | B32: Generative + Graph grounding | C32: 2000
A33: 4 | B33: Generative + 1 API action | C33: 1500
A34: 5 | B34: Generative + Graph + 2 actions | C34: 1000
A35: 6 | B35: Full autonomous invoice processing | C35: 500
A36: 7 | B36: Deep reasoning + action + Graph | C36: 200
A37: 8 | B37: Autonomous + translation + 3 actions | C37: 300
A39: User Type (Licensed/Unlicensed): | C39: Unlicensed
A41: PRICING (from Key Licensing Rules)
A42: PAYG rate per credit: | C42: ='Key Licensing Rules'!$D$5 -> 0.01 | D42: ← From Key Licensing Rules
A43: Capacity Pack cost: | C43: ='Key Licensing Rules'!$D$6 -> 160
A44: P3 rate per credit: | C44: ='Key Licensing Rules'!$D$7 -> 0.0095
A46: CREDIT CALCULATIONS BY SCENARIO
A47: # | B47: Interaction Scenario | C47: Monthly Volume | D47: Credits/Interaction | E47: Monthly Credits | F47: Always Billed?
...

Sheet 10-Public Website Agent
A1: Scenario 10: Public Website Agent Calculator
A3: Agent grounded on public URLs (no SharePoint). No Graph grounding charges. Still pays for generative answers.
A5: Credit Rate: 2 credits per generative answer (NO graph grounding surcharge)
A7: INPUT PARAMETERS | D7: ← Green cells are editable inputs
A8: Website visitors per month: | B8: 2000
A9: Questions per visitor: | B9: 3
A10: PAYG rate per credit: | B10: ='Key Licensing Rules'!$D$5 -> 0.01 | C10: ← From Key Licensing Rules
A11: Capacity Pack cost: | B11: ='Key Licensing Rules'!$D$6 -> 160 | C11: ← From Key Licensing Rules
A12: Capacity Pack credits: | B12: 25000
A14: NOTE: All external website users are unlicensed - credits always consumed
A16: CALCULATIONS
A17: Total generative answers per month: | B17: =B8*B9 -> 6000
A18: Credits per answer: | B18: 2
A19: Total monthly credits: | B19: =B17*B18 -> 12000
A21: COST COMPARISON
A22: Billing Model | B22: Monthly Cost | C22: Annual Cost | E22: Billing Option | F22: Monthly Cost
A23: Pay-As-You-Go (PAYG) | B23: =B19*'Key Licensing Rules'!$D$5 -> 120 | C23: =B23*12 -> 1440 | E23: PAYG | F23: =B23 -> 120
A24: Capacity Packs | B24: =IF(B19<25000, B19*('Key Licensing Rules'!$D$6/25000), CEILING(B19/25000,1)*'Key Licensing Rules'!$D$6) -> 76.8 | C24: =B24*12 -> 921.6 | E24: Capacity Packs | F24: =B24 -> 76.8
A25: P3 Plan | B25: =B19*'Key Licensing Rules'!$D$7 -> 114 | C25: =B25*12 -> 1368 | E25: P3 Plan | F25: =B25 -> 114
A26: Hybrid (CP + PAYG) | B26: =IF(B19<25000, MIN(B19*'Key Licensing Rules'!$D$5, B19*('Key Licensing Rules'!$D$6/25000)), QUOTIENT(B19,25000)*'Key Licensing Rules'!$D$6 + MOD(B19,25000)*'Key Licensing Rules'!$D$5) -> 76.8 | C26: =B26*12 -> 921.6 | E26: CP + PAYG | F26: =B26 -> 76.8
A27: Hybrid (CP + P3) | B27: =IF(B19<25000, MIN(B19*'Key Licensing Rules'!$D$7, B19*('Key Licensing Rules'!$D$6/25000)), QUOTIENT(B19,25000)*'Key Licensing Rules'!$D$6 + MOD(B19,25000)*'Key Licensing Rules'!$D$7) -> 76.8 | C27: =B27*12 -> 921.6 | E27: CP + P3 | F27: =B27 -> 76.8
A29: RECOMMENDATION
A30: RECOMMENDATION | B30: ="Monthly: "&TEXT(MIN(B23:B27),"[$$-en-US]#,##0.00")&" | Annual: "&TEXT(MIN(B23:B27)*12,"[$$-en-US]#,##0.00") -> Monthly: $76.80 | Annual: $921.60
A31: =INDEX(A23:A27,MATCH(MIN(B23:B27),B23:B27,0))&" is cheapest" -> Capacity Packs is cheapest | B31: ="Monthly: "&TEXT(MIN(B23:B27),"[$$-en-US]#,##0.00")&" | Annual: "&TEXT(MIN(B23:B27)*12,"[$$-en-US]#,##0.00") -> Monthly: $76.80 | Annual: $921.60
A32: 💡 TIP: Ensure Graph grounding is OFF to avoid 10-credit surcharge per response

Sheet 11-Agent Builder Lite
A1: Scenario 11: Agent Builder (Copilot Studio Lite) Calculator
A3: Agent Builder in M365 Copilot Chat. Special rule: Generative answers FREE if Graph grounding is OFF.
A5: ⚠️ CRITICAL BILLING RULE
A6: Outcome | B6: Licensed User | C6: Unlicensed User
A7: Uploaded files only, Graph OFF | B7: 0 credits (free) | C7: 0 credits (FREE!)
A8: SharePoint/OneDrive, Graph ON | B8: 0 credits (free) | C8: 12 credits (2+10)
A10: INPUT PARAMETERS | D10: ← Green cells are editable inputs
A11: Users per month: | B11: 500
A12: Queries per user: | B12: 5
A13: Graph Grounding (ON/OFF): | B13: ON
A14: User Type (Licensed/Unlicensed): | B14: Unlicensed
A15: PAYG rate per credit: | B15: ='Key Licensing Rules'!$D$5 -> 0.01 | C15: ← From Key Licensing Rules
A16: Capacity Pack cost: | B16: ='Key Licensing Rules'!$D$6 -> 160 | C16: ← From Key Licensing Rules
A17: Capacity Pack credits: | B17: 25000
A19: CALCULATIONS
A20: Total queries per month: | B20: =B11*B12 -> 2500
A21: Credits per query: | B21: =IF(UPPER(B14)="LICENSED",0,IF(UPPER(B13)="OFF",0,12)) -> 12 | C21: (0 if licensed, 0 if Graph OFF, else 12)
A22: Total monthly credits: | B22: =B20*B21 -> 30000
A24: COST COMPARISON
A25: Billing Model | B25: Monthly Cost | C25: Annual Cost | E25: Billing Option | F25: Monthly Cost
A26: Pay-As-You-Go (PAYG) | B26: =B22*'Key Licensing Rules'!$D$5 -> 300 | C26: =B26*12 -> 3600 | E26: PAYG | F26: =B26 -> 300
A27: Capacity Packs | B27: =IF(B22<25000, B22*('Key Licensing Rules'!$D$6/25000), CEILING(B22/25000,1)*'Key Licensing Rules'!$D$6) -> 320 | C27: =B27*12 -> 3840 | E27: Capacity Packs | F27: =B27 -> 320
A28: P3 Plan | B28: =B22*'Key Licensing Rules'!$D$7 -> 285 | C28: =B28*12 -> 3420 | E28: P3 Plan | F28: =B28 -> 285
A29: Hybrid (CP + PAYG) | B29: =IF(B22<25000, MIN(B22*'Key Licensing Rules'!$D$5, B22*('Key Licensing Rules'!$D$6/25000)), QUOTIENT(B22,25000)*'Key Licensing Rules'!$D$6 + MOD(B22,25000)*'Key Licensing Rules'!$D$5) -> 210 | C29: =B29*12 -> 2520 | E29: CP + PAYG | F29: =B29 -> 210
A30: Hybrid (CP + P3) | B30: =IF(B22<25000, MIN(B22*'Key Licensing Rules'!$D$7, B22*('Key Licensing Rules'!$D$6/25000)), QUOTIENT(B22,25000)*'Key Licensing Rules'!$D$6 + MOD(B22,25000)*'Key Licensing Rules'!$D$7) -> 207.5 | C30: =B30*12 -> 2490 | E30: CP + P3 | F30: =B30 -> 207.5
A32: RECOMMENDATION
A33: RECOMMENDATION | B33: ="Monthly: "&TEXT(MIN(B26:B30),"[$$-en-US]#,##0.00")&" | Annual: "&TEXT(MIN(B26:B30)*12,"[$$-en-US]#,##0.00") -> Monthly: $207.50 | Annual: $2,490.00
A34: =INDEX(A26:A30,MATCH(MIN(B26:B30),B26:B30,0))&" is cheapest" -> Hybrid (CP + P3) is cheapest | B34: ="Monthly: "&TEXT(MIN(B26:B30),"[$$-en-US]#,##0.00")&" | Annual: "&TEXT(MIN(B26:B30)*12,"[$$-en-US]#,##0.00") -> Monthly: $207.50 | Annual: $2,490.00
A35: 💡 TIP: Use Agent Builder with uploaded files and Graph OFF for FREE agent usage!

Sheet 12-External Channel
A1: Scenario 12: External Channel Agent Calculator
A3: Agents on external channels (website, WhatsApp, Messenger, mobile apps). ALL users billed - no license exceptions.
A5: ⚠️ ALL EXTERNAL CHANNEL USERS ARE ALWAYS BILLED - M365 licenses do not apply
A7: INPUT PARAMETERS | D7: ← Green cells are editable inputs
A8: Conversations per month: | B8: 5000
A9: Turns per conversation: | B9: 2
A10: % FAQ conversations (generative only): | B10: 70
A11: % Action conversations (gen+action): | B11: 30
A12: PAYG rate per credit: | B12: ='Key Licensing Rules'!$D$5 -> 0.01 | C12: ← From Key Licensing Rules
A13: Capacity Pack cost: | B13: ='Key Licensing Rules'!$D$6 -> 160 | C13: ← From Key Licensing Rules
A14: Capacity Pack credits: | B14: 25000
A16: CALCULATIONS
A17: FAQ conversations: | B17: =B8*(B10/100) -> 3500
A18: Action conversations: | B18: =B8*(B11/100) -> 1500
A19: Credits per FAQ conv: | B19: =B9*2 -> 4 | C19: (turns × 2 credits)
A20: Credits per Action conv: | B20: =(B9*2)+(1*5) -> 9 | C20: (turns×2 + 1 action×5)
A21: Total FAQ credits: | B21: =B17*B19 -> 14000
A22: Total Action credits: | B22: =B18*B20 -> 13500
A23: Total monthly credits: | B23: =B21+B22 -> 27500
A25: COST COMPARISON
A26: Billing Model | B26: Monthly Cost | C26: Annual Cost | E26: Billing Option | F26: Monthly Cost
A27: Pay-As-You-Go (PAYG) | B27: =B23*'Key Licensing Rules'!$D$5 -> 275 | C27: =B27*12 -> 3300 | E27: PAYG | F27: =B27 -> 275
A28: Capacity Packs | B28: =IF(B23<25000, B23*('Key Licensing Rules'!$D$6/25000), CEILING(B23/25000,1)*'Key Licensing Rules'!$D$6) -> 320 | C28: =B28*12 -> 3840 | E28: Capacity Packs | F28: =B28 -> 320
A29: P3 Plan | B29: =B23*'Key Licensing Rules'!$D$7 -> 261.25 | C29: =B29*12 -> 3135 | E29: P3 Plan | F29: =B29 -> 261.25
A30: Hybrid (CP + PAYG) | B30: =IF(B23<25000, MIN(B23*'Key Licensing Rules'!$D$5, B23*('Key Licensing Rules'!$D$6/25000)), QUOTIENT(B23,25000)*'Key Licensing Rules'!$D$6 + MOD(B23,25000)*'Key Licensing Rules'!$D$5) -> 185 | C30: =B30*12 -> 2220 | E30: CP + PAYG | F30: =B30 -> 185
A31: Hybrid (CP + P3) | B31: =IF(B23<25000, MIN(B23*'Key Licensing Rules'!$D$7, B23*('Key Licensing Rules'!$D$6/25000)), QUOTIENT(B23,25000)*'Key Licensing Rules'!$D$6 + MOD(B23,25000)*'Key Licensing Rules'!$D$7) -> 183.75 | C31: =B31*12 -> 2205 | E31: CP + P3 | F31: =B31 -> 183.75
A33: RECOMMENDATION
A34: RECOMMENDATION | B34: ="Monthly: "&TEXT(MIN(B27:B31),"[$$-en-US]#,##0.00")&" | Annual: "&TEXT(MIN(B27:B31)*12,"[$$-en-US]#,##0.00") -> Monthly: $183.75 | Annual: $2,205.00
A35: =INDEX(A27:A31,MATCH(MIN(B27:B31),B27:B31,0))&" is cheapest" -> Hybrid (CP + P3) is cheapest | B35: ="Monthly: "&TEXT(MIN(B27:B31),"[$$-en-US]#,##0.00")&" | Annual: "&TEXT(MIN(B27:B31)*12,"[$$-en-US]#,##0.00") -> Monthly: $183.75 | Annual: $2,205.00

Sheet 13-Proactive Greeting
A1: Scenario 13: Proactive Greeting Calculator
A3: Agent initiates greeting without user prompt. Billed even if user never responds. Hidden cost risk!
A5: ⚠️ WARNING: Credits consumed for EVERY greeting - even if 70% of users bounce without responding!
A7: Credit Rate: 1 Copilot Credit per proactive greeting (Classic Answer)
A9: INPUT PARAMETERS | D9: ← Green cells are editable inputs
A10: Visitors per day receiving greeting: | B10: 5000
A11: Days per month: | B11: 30
A12: % who engage after greeting: | B12: 30
A13: User Type (Licensed/Unlicensed): | B13: Unlicensed
A14: PAYG rate per credit: | B14: ='Key Licensing Rules'!$D$5 -> 0.01 | C14: ← From Key Licensing Rules
A15: Capacity Pack cost: | B15: ='Key Licensing Rules'!$D$6 -> 160 | C15: ← From Key Licensing Rules
A16: Capacity Pack credits: | B16: 25000
A18: CALCULATIONS
A19: Total greetings per month: | B19: =B10*B11 -> 150000
A20: Users who engage: | B20: =B19*(B12/100) -> 45000
A21: Users who bounce (wasted): | B21: =B19-B20 -> 105000
A22: Total greeting credits: | B22: =B19*1 -> 150000
A23: Is User Licensed: | B23: =IF(UPPER(B13)="LICENSED","Yes","No") -> No
A24: Billable Credits: | B24: =IF(B23="Yes",0,B22) -> 150000
A26: COST ANALYSIS
A27: Wasted credits (bounced users): | B27: =IF(B23="Yes",0,B21) -> 105000
A28: Wasted cost per month: | B28: =B27*B14 -> 1050
A30: COST COMPARISON
A31: Billing Model | B31: Monthly Cost | C31: Annual Cost | E31: Billing Option | F31: Monthly Cost
A32: Pay-As-You-Go (PAYG) | B32: =B24*'Key Licensing Rules'!$D$5 -> 1500 | C32: =B32*12 -> 18000 | E32: PAYG | F32: =B32 -> 1500
A33: Capacity Packs | B33: =IF(B24<25000, B24*('Key Licensing Rules'!$D$6/25000), CEILING(B24/25000,1)*'Key Licensing Rules'!$D$6) -> 960 | C33: =B33*12 -> 11520 | E33: Capacity Packs | F33: =B33 -> 960
A34: P3 Plan | B34: =B24*'Key Licensing Rules'!$D$7 -> 1425 | C34: =B34*12 -> 17100 | E34: P3 Plan | F34: =B34 -> 1425
A35: Hybrid (CP + PAYG) | B35: =IF(B24<25000, MIN(B24*'Key Licensing Rules'!$D$5, B24*('Key Licensing Rules'!$D$6/25000)), QUOTIENT(B24,25000)*'Key Licensing Rules'!$D$6 + MOD(B24,25000)*'Key Licensing Rules'!$D$5) -> 960 | C35: =B35*12 -> 11520 | E35: CP + PAYG | F35: =B35 -> 960
A36: Hybrid (CP + P3) | B36: =IF(B24<25000, MIN(B24*'Key Licensing Rules'!$D$7, B24*('Key Licensing Rules'!$D$6/25000)), QUOTIENT(B24,25000)*'Key Licensing Rules'!$D$6 + MOD(B24,25000)*'Key Licensing Rules'!$D$7) -> 960 | C36: =B36*12 -> 11520 | E36: CP + P3 | F36: =B36 -> 960
A38: 💡 DESIGN TIP: Use user-initiated model (click to chat) instead of auto-greeting to eliminate waste
A40: RECOMMENDATION
A41: RECOMMENDATION | B41: ="Monthly: "&TEXT(MIN(B32:B36),"[$$-en-US]#,##0.00")&" | Annual: "&TEXT(MIN(B32:B36)*12,"[$$-en-US]#,##0.00") -> Monthly: $960.00 | Annual: $11,520.00
A42: =INDEX(A32:A36,MATCH(MIN(B32:B36),B32:B36,0))&" is cheapest" -> Capacity Packs is cheapest | B42: ="Monthly: "&TEXT(MIN(B32:B36),"[$$-en-US]#,##0.00")&" | Annual: "&TEXT(MIN(B32:B36)*12,"[$$-en-US]#,##0.00") -> Monthly: $960.00 | Annual: $11,520.00

Sheet 14-Testing vs Prod
A1: Scenario 14: Testing vs Production - What Gets Billed
A3: Understanding what's billed during development vs production testing.
A5: TESTING BILLING RULES
A6: Activity | B6: During Test Chat | C6: Published/Production
A7: Classic answer | B7: NOT billed | C7: Billed (1 credit)
A8: Generative answer | B8: NOT billed | C8: Billed (2 credits)
A9: Agent action (connector) | B9: NOT billed | C9: Billed (5 credits)
A10: Graph grounding | B10: NOT billed | C10: Billed (10 credits)
A11: Agent flow actions | B11: BILLED | C11: Billed (13/100)
A12: AI Tools (Basic/Std/Premium) | B12: BILLED | C12: Billed
A13: Content processing (OCR) | B13: BILLED | C13: Billed (8/page)
A14: Preview features | B14: BILLED | C14: Billed
A16: TESTING COST CALCULATOR | D16: ← Green cells are editable inputs
A17: Test conversations (simple FAQ): | B17: 200
A18: Test conversations with flows: | B18: 100
A19: Flow actions per test: | B19: 50
A20: Documents processed in tests: | B20: 50
A21: Pages per document: | B21: 3
A22: PRICING (from Key Licensing Rules)
A23: PAYG rate per credit: | B23: ='Key Licensing Rules'!$D$5 -> 0.01 | C23: ← From Key Licensing Rules
A25: TESTING COST CALCULATIONS
A26: Simple FAQ tests (free): | B26: 0 | C26: (test chat exempt)
A27: Flow test credits: | B27: =B18*B19/100*13 -> 650
A28: Document processing credits: | B28: =B20*B21*8 -> 1200
A29: Total testing credits: | B29: =B27+B28 -> 1850
A31: COST COMPARISON
A32: Billing Model | B32: Testing Cost | C32: Notes | E32: Test Type | F32: Credits
A33: Pay-As-You-Go (PAYG) | B33: =B29*'Key Licensing Rules'!$D$5 -> 18.5 | C33: Credits × PAYG Rate | E33: CP + PAYG | F33: =B35 -> 11.84
A34: P3 Plan | B34: =B29*'Key Licensing Rules'!$D$7 -> 17.575 | C34: Credits × P3 Rate | E34: CP + P3 | F34: =B36 -> 11.84
A35: Hybrid (CP + PAYG) | B35: =IF(B29<25000, MIN(B29*'Key Licensing Rules'!$D$5, B29*('Key Licensing Rules'!$D$6/25000)), QUOTIENT(B29,25000)*'Key Licensing Rules'!$D$6 + MOD(B29,25000)*'Key Licensing Rules'!$D$5) -> 11.84 | C35: =B35*12 -> 142.08 | E35: Doc Processing | F35: =B28 -> 1200
A36: Hybrid (CP + P3) | B36: =IF(B29<25000, MIN(B29*'Key Licensing Rules'!$D$7, B29*('Key Licensing Rules'!$D$6/25000)), QUOTIENT(B29,25000)*'Key Licensing Rules'!$D$6 + MOD(B29,25000)*'Key Licensing Rules'!$D$7) -> 11.84 | C36: =B36*12 -> 142.08
A37: • Non-production environments (Dev, Test) consume credits when agents run
A38: • Failed/errored responses still consume credits once processing begins
A39: • Retrying a question costs additional credits
A40: • Adding knowledge sources does NOT consume credits
A42: RECOMMENDATION
A43: =INDEX(A33:A36,MATCH(MIN(B33:B36),B33:B36,0))&" is cheapest for testing" -> Hybrid (CP + PAYG) is cheapest for testing | B43: ="Testing Cost: "&TEXT(MIN(B33:B36),"[$$-en-US]#,##0.00") -> Testing Cost: $11.84
A44: RECOMMENDATION
A45: =INDEX(A33:A36,MATCH(MIN(B33:B36),B33:B36,0))&" is cheapest for testing" -> Hybrid (CP + PAYG) is cheapest for testing | B45: ="Testing Cost: "&TEXT(MIN(B33:B36),"[$$-en-US]#,##0.00") -> Testing Cost: $11.84

Sheet 15-Teams Comparison
A1: Scenario 15: Copilot Studio for Teams vs Standalone → Teams
A3: Two ways to deploy agents to Teams with VERY different billing!
A5: DEPLOYMENT COMPARISON
A6: Feature | B6: Copilot Studio for Teams | C6: Standalone → Teams
A7: Built where | B7: Inside Microsoft Teams | C7: copilotstudio.microsoft.com
A8: License required | B8: No (included with M365) | C8: Yes (PAYG or Capacity)
A9: Credits consumed | B9: NEVER | C9: Yes (except M365 Copilot B2E)
A10: Premium connectors | B10: No | C10: Yes
A11: Agent flows | B11: No | C11: Yes
A12: Graph grounding | B12: No | C12: Yes
A13: Autonomous triggers | B13: No | C13: Yes
A14: External channels | B14: No | C14: Yes
A16: STANDALONE → TEAMS COST CALCULATOR | D16: ← Green cells are editable inputs
A17: Total employees using agent: | B17: 1000
A18: Employees with M365 Copilot license: | B18: 300
A19: Unlicensed employees: | B19: =B17-B18 -> 700
A20: Interactions per month per user: | B20: 3
A21: Credits per interaction (gen+action): | B21: 7
A22: PRICING (from Key Licensing Rules)
A23: PAYG rate per credit: | B23: ='Key Licensing Rules'!$D$5 -> 0.01 | C23: ← From Key Licensing Rules
A25: STANDALONE → TEAMS COST CALCULATIONS
A26: Licensed user credits: | B26: 0 | C26: (always $0)
A27: Unlicensed user credits: | B27: =B19*B20*B21 -> 14700
A29: COST COMPARISON
A30: Billing Model | B30: Monthly Cost | C30: Annual Cost | E30: Deployment Type | F30: Monthly Cost
A31: Pay-As-You-Go (PAYG) | B31: =B27*'Key Licensing Rules'!$D$5 -> 147 | C31: =B31*12 -> 1764 | E31: PAYG | F31: =B31 -> 147
A32: Capacity Packs | B32: =IF(B27<25000, B27*('Key Licensing Rules'!$D$6/25000), CEILING(B27/25000,1)*'Key Licensing Rules'!$D$6) -> 94.08 | C32: =B32*12 -> 1128.96 | E32: Capacity Packs | F32: =B32 -> 94.08
A33: P3 Plan | B33: =B27*'Key Licensing Rules'!$D$7 -> 139.65 | C33: =B33*12 -> 1675.8 | E33: P3 Plan | F33: =B33 -> 139.65
A34: Hybrid (CP + PAYG) | B34: =IF(B27<25000, MIN(B27*'Key Licensing Rules'!$D$5, B27*('Key Licensing Rules'!$D$6/25000)), QUOTIENT(B27,25000)*'Key Licensing Rules'!$D$6 + MOD(B27,25000)*'Key Licensing Rules'!$D$5) -> 94.08 | C34: =B34*12 -> 1128.96 | E34: CP + PAYG | F34: =B34 -> 94.08
A35: Hybrid (CP + P3) | B35: =IF(B27<25000, MIN(B27*'Key Licensing Rules'!$D$7, B27*('Key Licensing Rules'!$D$6/25000)), QUOTIENT(B27,25000)*'Key Licensing Rules'!$D$6 + MOD(B27,25000)*'Key Licensing Rules'!$D$7) -> 94.08 | C35: =B35*12 -> 1128.96 | E35: CP + P3 | F35: =B35 -> 94.08
A36: Copilot Studio for Teams | B36: 0 | C36: 0 | D36: (free, limited features)
A38: 💡 RECOMMENDATION
A39: Use Copilot Studio for Teams for simple FAQ bots (free)
A40: Use Standalone for premium connectors, flows, Graph, autonomous triggers
A42: BEST PAID OPTION: | B42: =INDEX(A31:A35,MATCH(MIN(B31:B35),B31:B35,0))&" is cheapest" -> Capacity Packs is cheapest | C42: ="Monthly: "&TEXT(MIN(B31:B35),"[$$-en-US]#,##0.00") -> Monthly: $94.08
A43: BEST PAID OPTION: | B43: =INDEX(A31:A35,MATCH(MIN(B31:B35),B31:B35,0))&" is cheapest" -> Capacity Packs is cheapest | C43: ="Monthly: "&TEXT(MIN(B31:B35),"[$$-en-US]#,##0.00") -> Monthly: $94.08
